<?xml version="1.0" encoding="UTF-8"?>
<testng-results skipped="0" failed="4" ignored="0" total="5" passed="1">
  <reporter-output>
  </reporter-output>
  <suite name="Default suite" duration-ms="45069" started-at="2019-08-02T11:24:51Z" finished-at="2019-08-02T11:25:36Z">
    <groups>
    </groups>
    <test name="Default test" duration-ms="45069" started-at="2019-08-02T11:24:51Z" finished-at="2019-08-02T11:25:36Z">
      <class name="satyam.mandal.testng.Before_After_annotation">
        <test-method status="PASS" signature="open_function()[pri:0, instance:satyam.mandal.testng.Before_After_annotation@51081592]" name="open_function" is-config="true" duration-ms="7633" started-at="2019-08-02T11:24:51Z" finished-at="2019-08-02T11:24:58Z">
          <reporter-output>
          </reporter-output>
        </test-method> <!-- open_function -->
        <test-method status="PASS" signature="set_data_function()[pri:0, instance:satyam.mandal.testng.Before_After_annotation@51081592]" name="set_data_function" duration-ms="1547" started-at="2019-08-02T11:24:58Z" finished-at="2019-08-02T11:25:00Z">
          <reporter-output>
          </reporter-output>
        </test-method> <!-- set_data_function -->
        <test-method status="PASS" signature="close()[pri:0, instance:satyam.mandal.testng.Before_After_annotation@51081592]" name="close" is-config="true" duration-ms="102" started-at="2019-08-02T11:25:00Z" finished-at="2019-08-02T11:25:00Z">
          <reporter-output>
          </reporter-output>
        </test-method> <!-- close -->
        <test-method status="PASS" signature="open_function()[pri:0, instance:satyam.mandal.testng.Before_After_annotation@51081592]" name="open_function" is-config="true" duration-ms="7298" started-at="2019-08-02T11:25:00Z" finished-at="2019-08-02T11:25:07Z">
          <reporter-output>
          </reporter-output>
        </test-method> <!-- open_function -->
        <test-method status="FAIL" signature="set_data_function2()[pri:0, instance:satyam.mandal.testng.Before_After_annotation@51081592]" name="set_data_function2" duration-ms="1325" started-at="2019-08-02T11:25:07Z" finished-at="2019-08-02T11:25:09Z">
          <exception class="java.lang.AssertionError">
            <message>
              <![CDATA[expected [The credentials provided are incorrect] but found [checklist@gmail.com]]]>
            </message>
            <full-stacktrace>
              <![CDATA[java.lang.AssertionError: expected [The credentials provided are incorrect] but found [checklist@gmail.com]
at org.testng.Assert.fail(Assert.java:96)
at org.testng.Assert.failNotEquals(Assert.java:776)
at org.testng.Assert.assertEqualsImpl(Assert.java:137)
at org.testng.Assert.assertEquals(Assert.java:118)
at org.testng.Assert.assertEquals(Assert.java:453)
at org.testng.Assert.assertEquals(Assert.java:463)
at satyam.mandal.testng.Before_After_annotation.set_data_function2(Before_After_annotation.java:39)
at sun.reflect.NativeMethodAccessorImpl.invoke0(Native Method)
at sun.reflect.NativeMethodAccessorImpl.invoke(Unknown Source)
at sun.reflect.DelegatingMethodAccessorImpl.invoke(Unknown Source)
at java.lang.reflect.Method.invoke(Unknown Source)
at org.testng.internal.MethodInvocationHelper.invokeMethod(MethodInvocationHelper.java:124)
at org.testng.internal.Invoker.invokeMethod(Invoker.java:583)
at org.testng.internal.Invoker.invokeTestMethod(Invoker.java:719)
at org.testng.internal.Invoker.invokeTestMethods(Invoker.java:989)
at org.testng.internal.TestMethodWorker.invokeTestMethods(TestMethodWorker.java:125)
at org.testng.internal.TestMethodWorker.run(TestMethodWorker.java:109)
at org.testng.TestRunner.privateRun(TestRunner.java:648)
at org.testng.TestRunner.run(TestRunner.java:505)
at org.testng.SuiteRunner.runTest(SuiteRunner.java:455)
at org.testng.SuiteRunner.runSequentially(SuiteRunner.java:450)
at org.testng.SuiteRunner.privateRun(SuiteRunner.java:415)
at org.testng.SuiteRunner.run(SuiteRunner.java:364)
at org.testng.SuiteRunnerWorker.runSuite(SuiteRunnerWorker.java:52)
at org.testng.SuiteRunnerWorker.run(SuiteRunnerWorker.java:84)
at org.testng.TestNG.runSuitesSequentially(TestNG.java:1208)
at org.testng.TestNG.runSuitesLocally(TestNG.java:1137)
at org.testng.TestNG.runSuites(TestNG.java:1049)
at org.testng.TestNG.run(TestNG.java:1017)
at org.testng.remote.AbstractRemoteTestNG.run(AbstractRemoteTestNG.java:115)
at org.testng.remote.RemoteTestNG.initAndRun(RemoteTestNG.java:251)
at org.testng.remote.RemoteTestNG.main(RemoteTestNG.java:77)
]]>
            </full-stacktrace>
          </exception> <!-- java.lang.AssertionError -->
          <reporter-output>
          </reporter-output>
        </test-method> <!-- set_data_function2 -->
        <test-method status="PASS" signature="close()[pri:0, instance:satyam.mandal.testng.Before_After_annotation@51081592]" name="close" is-config="true" duration-ms="92" started-at="2019-08-02T11:25:09Z" finished-at="2019-08-02T11:25:09Z">
          <reporter-output>
          </reporter-output>
        </test-method> <!-- close -->
        <test-method status="PASS" signature="open_function()[pri:0, instance:satyam.mandal.testng.Before_After_annotation@51081592]" name="open_function" is-config="true" duration-ms="7832" started-at="2019-08-02T11:25:09Z" finished-at="2019-08-02T11:25:17Z">
          <reporter-output>
          </reporter-output>
        </test-method> <!-- open_function -->
        <test-method status="FAIL" signature="set_data_function3()[pri:0, instance:satyam.mandal.testng.Before_After_annotation@51081592]" name="set_data_function3" duration-ms="819" started-at="2019-08-02T11:25:17Z" finished-at="2019-08-02T11:25:17Z">
          <exception class="java.lang.AssertionError">
            <message>
              <![CDATA[The following asserts failed:
expected [Please enter a valid email address.] but found [cbin$#12.com]]]>
            </message>
            <full-stacktrace>
              <![CDATA[java.lang.AssertionError: The following asserts failed:
expected [Please enter a valid email address.] but found [cbin$#12.com]
at org.testng.asserts.SoftAssert.assertAll(SoftAssert.java:43)
at satyam.mandal.testng.Before_After_annotation.set_data_function3(Before_After_annotation.java:53)
at sun.reflect.NativeMethodAccessorImpl.invoke0(Native Method)
at sun.reflect.NativeMethodAccessorImpl.invoke(Unknown Source)
at sun.reflect.DelegatingMethodAccessorImpl.invoke(Unknown Source)
at java.lang.reflect.Method.invoke(Unknown Source)
at org.testng.internal.MethodInvocationHelper.invokeMethod(MethodInvocationHelper.java:124)
at org.testng.internal.Invoker.invokeMethod(Invoker.java:583)
at org.testng.internal.Invoker.invokeTestMethod(Invoker.java:719)
at org.testng.internal.Invoker.invokeTestMethods(Invoker.java:989)
at org.testng.internal.TestMethodWorker.invokeTestMethods(TestMethodWorker.java:125)
at org.testng.internal.TestMethodWorker.run(TestMethodWorker.java:109)
at org.testng.TestRunner.privateRun(TestRunner.java:648)
at org.testng.TestRunner.run(TestRunner.java:505)
at org.testng.SuiteRunner.runTest(SuiteRunner.java:455)
at org.testng.SuiteRunner.runSequentially(SuiteRunner.java:450)
at org.testng.SuiteRunner.privateRun(SuiteRunner.java:415)
at org.testng.SuiteRunner.run(SuiteRunner.java:364)
at org.testng.SuiteRunnerWorker.runSuite(SuiteRunnerWorker.java:52)
at org.testng.SuiteRunnerWorker.run(SuiteRunnerWorker.java:84)
at org.testng.TestNG.runSuitesSequentially(TestNG.java:1208)
at org.testng.TestNG.runSuitesLocally(TestNG.java:1137)
at org.testng.TestNG.runSuites(TestNG.java:1049)
at org.testng.TestNG.run(TestNG.java:1017)
at org.testng.remote.AbstractRemoteTestNG.run(AbstractRemoteTestNG.java:115)
at org.testng.remote.RemoteTestNG.initAndRun(RemoteTestNG.java:251)
at org.testng.remote.RemoteTestNG.main(RemoteTestNG.java:77)
]]>
            </full-stacktrace>
          </exception> <!-- java.lang.AssertionError -->
          <reporter-output>
          </reporter-output>
        </test-method> <!-- set_data_function3 -->
        <test-method status="PASS" signature="close()[pri:0, instance:satyam.mandal.testng.Before_After_annotation@51081592]" name="close" is-config="true" duration-ms="83" started-at="2019-08-02T11:25:17Z" finished-at="2019-08-02T11:25:17Z">
          <reporter-output>
          </reporter-output>
        </test-method> <!-- close -->
        <test-method status="PASS" signature="open_function()[pri:0, instance:satyam.mandal.testng.Before_After_annotation@51081592]" name="open_function" is-config="true" duration-ms="7106" started-at="2019-08-02T11:25:17Z" finished-at="2019-08-02T11:25:25Z">
          <reporter-output>
          </reporter-output>
        </test-method> <!-- open_function -->
        <test-method status="FAIL" signature="set_data_function4()[pri:0, instance:satyam.mandal.testng.Before_After_annotation@51081592]" name="set_data_function4" duration-ms="1269" started-at="2019-08-02T11:25:25Z" finished-at="2019-08-02T11:25:26Z">
          <exception class="java.lang.AssertionError">
            <message>
              <![CDATA[expected [No customer account found] but found [temp11@gmail.com]]]>
            </message>
            <full-stacktrace>
              <![CDATA[java.lang.AssertionError: expected [No customer account found] but found [temp11@gmail.com]
at org.testng.Assert.fail(Assert.java:96)
at org.testng.Assert.failNotEquals(Assert.java:776)
at org.testng.Assert.assertEqualsImpl(Assert.java:137)
at org.testng.Assert.assertEquals(Assert.java:118)
at org.testng.Assert.assertEquals(Assert.java:453)
at org.testng.Assert.assertEquals(Assert.java:463)
at satyam.mandal.testng.Before_After_annotation.set_data_function4(Before_After_annotation.java:63)
at sun.reflect.NativeMethodAccessorImpl.invoke0(Native Method)
at sun.reflect.NativeMethodAccessorImpl.invoke(Unknown Source)
at sun.reflect.DelegatingMethodAccessorImpl.invoke(Unknown Source)
at java.lang.reflect.Method.invoke(Unknown Source)
at org.testng.internal.MethodInvocationHelper.invokeMethod(MethodInvocationHelper.java:124)
at org.testng.internal.Invoker.invokeMethod(Invoker.java:583)
at org.testng.internal.Invoker.invokeTestMethod(Invoker.java:719)
at org.testng.internal.Invoker.invokeTestMethods(Invoker.java:989)
at org.testng.internal.TestMethodWorker.invokeTestMethods(TestMethodWorker.java:125)
at org.testng.internal.TestMethodWorker.run(TestMethodWorker.java:109)
at org.testng.TestRunner.privateRun(TestRunner.java:648)
at org.testng.TestRunner.run(TestRunner.java:505)
at org.testng.SuiteRunner.runTest(SuiteRunner.java:455)
at org.testng.SuiteRunner.runSequentially(SuiteRunner.java:450)
at org.testng.SuiteRunner.privateRun(SuiteRunner.java:415)
at org.testng.SuiteRunner.run(SuiteRunner.java:364)
at org.testng.SuiteRunnerWorker.runSuite(SuiteRunnerWorker.java:52)
at org.testng.SuiteRunnerWorker.run(SuiteRunnerWorker.java:84)
at org.testng.TestNG.runSuitesSequentially(TestNG.java:1208)
at org.testng.TestNG.runSuitesLocally(TestNG.java:1137)
at org.testng.TestNG.runSuites(TestNG.java:1049)
at org.testng.TestNG.run(TestNG.java:1017)
at org.testng.remote.AbstractRemoteTestNG.run(AbstractRemoteTestNG.java:115)
at org.testng.remote.RemoteTestNG.initAndRun(RemoteTestNG.java:251)
at org.testng.remote.RemoteTestNG.main(RemoteTestNG.java:77)
]]>
            </full-stacktrace>
          </exception> <!-- java.lang.AssertionError -->
          <reporter-output>
          </reporter-output>
        </test-method> <!-- set_data_function4 -->
        <test-method status="PASS" signature="close()[pri:0, instance:satyam.mandal.testng.Before_After_annotation@51081592]" name="close" is-config="true" duration-ms="88" started-at="2019-08-02T11:25:26Z" finished-at="2019-08-02T11:25:26Z">
          <reporter-output>
          </reporter-output>
        </test-method> <!-- close -->
        <test-method status="PASS" signature="open_function()[pri:0, instance:satyam.mandal.testng.Before_After_annotation@51081592]" name="open_function" is-config="true" duration-ms="8767" started-at="2019-08-02T11:25:26Z" finished-at="2019-08-02T11:25:35Z">
          <reporter-output>
          </reporter-output>
        </test-method> <!-- open_function -->
        <test-method status="FAIL" signature="set_data_function5()[pri:0, instance:satyam.mandal.testng.Before_After_annotation@51081592]" name="set_data_function5" duration-ms="1008" started-at="2019-08-02T11:25:35Z" finished-at="2019-08-02T11:25:36Z">
          <exception class="java.lang.AssertionError">
            <message>
              <![CDATA[expected [No customer account found] but found []]]>
            </message>
            <full-stacktrace>
              <![CDATA[java.lang.AssertionError: expected [No customer account found] but found []
at org.testng.Assert.fail(Assert.java:96)
at org.testng.Assert.failNotEquals(Assert.java:776)
at org.testng.Assert.assertEqualsImpl(Assert.java:137)
at org.testng.Assert.assertEquals(Assert.java:118)
at org.testng.Assert.assertEquals(Assert.java:453)
at org.testng.Assert.assertEquals(Assert.java:463)
at satyam.mandal.testng.Before_After_annotation.set_data_function5(Before_After_annotation.java:73)
at sun.reflect.NativeMethodAccessorImpl.invoke0(Native Method)
at sun.reflect.NativeMethodAccessorImpl.invoke(Unknown Source)
at sun.reflect.DelegatingMethodAccessorImpl.invoke(Unknown Source)
at java.lang.reflect.Method.invoke(Unknown Source)
at org.testng.internal.MethodInvocationHelper.invokeMethod(MethodInvocationHelper.java:124)
at org.testng.internal.Invoker.invokeMethod(Invoker.java:583)
at org.testng.internal.Invoker.invokeTestMethod(Invoker.java:719)
at org.testng.internal.Invoker.invokeTestMethods(Invoker.java:989)
at org.testng.internal.TestMethodWorker.invokeTestMethods(TestMethodWorker.java:125)
at org.testng.internal.TestMethodWorker.run(TestMethodWorker.java:109)
at org.testng.TestRunner.privateRun(TestRunner.java:648)
at org.testng.TestRunner.run(TestRunner.java:505)
at org.testng.SuiteRunner.runTest(SuiteRunner.java:455)
at org.testng.SuiteRunner.runSequentially(SuiteRunner.java:450)
at org.testng.SuiteRunner.privateRun(SuiteRunner.java:415)
at org.testng.SuiteRunner.run(SuiteRunner.java:364)
at org.testng.SuiteRunnerWorker.runSuite(SuiteRunnerWorker.java:52)
at org.testng.SuiteRunnerWorker.run(SuiteRunnerWorker.java:84)
at org.testng.TestNG.runSuitesSequentially(TestNG.java:1208)
at org.testng.TestNG.runSuitesLocally(TestNG.java:1137)
at org.testng.TestNG.runSuites(TestNG.java:1049)
at org.testng.TestNG.run(TestNG.java:1017)
at org.testng.remote.AbstractRemoteTestNG.run(AbstractRemoteTestNG.java:115)
at org.testng.remote.RemoteTestNG.initAndRun(RemoteTestNG.java:251)
at org.testng.remote.RemoteTestNG.main(RemoteTestNG.java:77)
]]>
            </full-stacktrace>
          </exception> <!-- java.lang.AssertionError -->
          <reporter-output>
          </reporter-output>
        </test-method> <!-- set_data_function5 -->
        <test-method status="PASS" signature="close()[pri:0, instance:satyam.mandal.testng.Before_After_annotation@51081592]" name="close" is-config="true" duration-ms="76" started-at="2019-08-02T11:25:36Z" finished-at="2019-08-02T11:25:36Z">
          <reporter-output>
          </reporter-output>
        </test-method> <!-- close -->
      </class> <!-- satyam.mandal.testng.Before_After_annotation -->
    </test> <!-- Default test -->
  </suite> <!-- Default suite -->
</testng-results>
